<robot name="simple_putter">
  <link name="putter_head">
	<inertial>
	  <origin xyz="0.025 0 0" />
	  <mass value=".1" />
	  <inertia  ixx="1.0" ixy="0.0"  ixz="0.0"  iyy="1.0"  iyz="0.0"  izz="1.0" />
	</inertial>
	<visual>
	  <origin xyz="0.025 0 0"/>
	  <geometry>
	    <box size=".125 .025 .025"/>
	  </geometry>
	</visual>
	<collision>
      <origin xyz="0.025 0 0"/>
      <geometry>
        <box size=".125 .025 .025" />
      </geometry>
	</collision>
  </link>
  <link name="putter_body">
    <inertial>
      <origin xyz="0 0 0" /> 
      <mass value=".5" />
      <inertia  ixx="1.0" ixy="0.0"  ixz="0.0"  iyy="1.0"  iyz="0.0"  izz="1.0" />
    </inertial>
    <visual>
      <origin xyz="0 0 0"/>
      <geometry>
        <box size=".025 .025 .5" />
      </geometry>
    </visual>
    <collision>
      <origin xyz="0 0 0"/>
      <geometry>
        <box size=".025 .025 .5" />
      </geometry>
    </collision>
  </link>

  <link name="putter_top">
    <inertial>
      <origin xyz="0 0 0" />
      <mass value="0.1" />
      <inertia  ixx="0.1" ixy="0.0"  ixz="0.0"  iyy="0.1"  iyz="0.0"  izz="0.1" />
    </inertial>
    <visual>
      <origin xyz="0 0 0"/>
      <geometry>
        <box size=".025 .125 .025" />
      </geometry>
    </visual>
    <collision>
      <origin xyz="0 0 0"/>
      <geometry>
        <box size=".025 .125 .025" />
      </geometry>
    </collision>
  </link>

  <joint name="putter_joint" type="continuous">
    <parent link="putter_body"/>
    <child link="putter_head"/>
    <origin rpy="0 0 0" xyz="0 0 -.25"/>
  </joint>

  <joint name="top_joint" type="continuous">
    <parent link="putter_body"/>
    <child link="putter_top"/>
    <origin rpy="0 0 0" xyz="0 0 0.25"/>
  </joint>

  <gazebo reference="my_putter">
    <material>Gazebo/Blue</material>
  </gazebo>
</robot>
